[2025-04-12T06:07:41.067+0000] {local_task_job_runner.py:123} INFO - ::group::Pre task execution logs
[2025-04-12T06:07:41.076+0000] {taskinstance.py:2613} INFO - Dependencies all met for dep_context=non-requeueable deps ti=<TaskInstance: triphobo_etl_pipeline.load_attractions_snowflake manual__2025-04-12T05:57:19.595174+00:00 [queued]>
[2025-04-12T06:07:41.080+0000] {taskinstance.py:2613} INFO - Dependencies all met for dep_context=requeueable deps ti=<TaskInstance: triphobo_etl_pipeline.load_attractions_snowflake manual__2025-04-12T05:57:19.595174+00:00 [queued]>
[2025-04-12T06:07:41.080+0000] {taskinstance.py:2866} INFO - Starting attempt 1 of 1
[2025-04-12T06:07:41.086+0000] {taskinstance.py:2889} INFO - Executing <Task(PythonOperator): load_attractions_snowflake> on 2025-04-12 05:57:19.595174+00:00
[2025-04-12T06:07:41.090+0000] {warnings.py:112} WARNING - /home/***/.local/lib/python3.12/site-packages/***/task/task_runner/standard_task_runner.py:70: DeprecationWarning: This process (pid=1230) is multi-threaded, use of fork() may lead to deadlocks in the child.
  pid = os.fork()

[2025-04-12T06:07:41.091+0000] {standard_task_runner.py:72} INFO - Started process 1231 to run task
[2025-04-12T06:07:41.092+0000] {standard_task_runner.py:104} INFO - Running: ['***', 'tasks', 'run', 'triphobo_etl_pipeline', 'load_attractions_snowflake', 'manual__2025-04-12T05:57:19.595174+00:00', '--job-id', '140', '--raw', '--subdir', 'DAGS_FOLDER/trip_dag.py', '--cfg-path', '/tmp/tmp36doqgg0']
[2025-04-12T06:07:41.094+0000] {standard_task_runner.py:105} INFO - Job 140: Subtask load_attractions_snowflake
[2025-04-12T06:07:41.117+0000] {task_command.py:467} INFO - Running <TaskInstance: triphobo_etl_pipeline.load_attractions_snowflake manual__2025-04-12T05:57:19.595174+00:00 [running]> on host 0032dfa832cd
[2025-04-12T06:07:41.154+0000] {taskinstance.py:3132} INFO - Exporting env vars: AIRFLOW_CTX_DAG_OWNER='***' AIRFLOW_CTX_DAG_ID='triphobo_etl_pipeline' AIRFLOW_CTX_TASK_ID='load_attractions_snowflake' AIRFLOW_CTX_EXECUTION_DATE='2025-04-12T05:57:19.595174+00:00' AIRFLOW_CTX_TRY_NUMBER='1' AIRFLOW_CTX_DAG_RUN_ID='manual__2025-04-12T05:57:19.595174+00:00'
[2025-04-12T06:07:41.155+0000] {taskinstance.py:731} INFO - ::endgroup::
[2025-04-12T06:07:41.166+0000] {connection.py:414} INFO - Snowflake Connector for Python Version: 3.12.4, Python Version: 3.12.8, Platform: Linux-6.10.14-linuxkit-aarch64-with-glibc2.36
[2025-04-12T06:07:41.167+0000] {connection.py:1197} INFO - Connecting to GLOBAL Snowflake domain
[2025-04-12T06:07:41.167+0000] {connection.py:1278} INFO - This connection is in OCSP Fail Open Mode. TLS Certificates would be checked for validity and revocation status. Any other Certificate Revocation related exceptions or OCSP Responder failures would be disregarded in favor of connectivity.
[2025-04-12T06:07:42.128+0000] {upload_to_snowflake.py:36} INFO - Creating table `TRIPHOBO_ATTRACTIONS` if it doesn't exist...
[2025-04-12T06:07:42.568+0000] {cursor.py:1166} INFO - Number of results in first chunk: 1
[2025-04-12T06:07:42.569+0000] {upload_to_snowflake.py:41} INFO - Staging local file /tmp/triphobo_data/cleaned_attractions.csv to Snowflake...
[2025-04-12T06:07:42.690+0000] {upload_to_snowflake.py:60} ERROR - Error uploading to Snowflake: 002003 (02000): 01bba22f-020d-009b-000b-5e4b002d701a: SQL compilation error:
Stage 'FINAL_PROJECT.SCRAPING.DATA' does not exist or not authorized.
[2025-04-12T06:07:42.691+0000] {taskinstance.py:3311} ERROR - Task failed with exception
Traceback (most recent call last):
  File "/home/airflow/.local/lib/python3.12/site-packages/airflow/models/taskinstance.py", line 767, in _execute_task
    result = _execute_callable(context=context, **execute_callable_kwargs)
             ^^^^^^^^^^^^^^^^^^^^^^^^^^^^^^^^^^^^^^^^^^^^^^^^^^^^^^^^^^^^^
  File "/home/airflow/.local/lib/python3.12/site-packages/airflow/models/taskinstance.py", line 733, in _execute_callable
    return ExecutionCallableRunner(
           ^^^^^^^^^^^^^^^^^^^^^^^^
  File "/home/airflow/.local/lib/python3.12/site-packages/airflow/utils/operator_helpers.py", line 252, in run
    return self.func(*args, **kwargs)
           ^^^^^^^^^^^^^^^^^^^^^^^^^^
  File "/home/airflow/.local/lib/python3.12/site-packages/airflow/models/baseoperator.py", line 422, in wrapper
    return func(self, *args, **kwargs)
           ^^^^^^^^^^^^^^^^^^^^^^^^^^^
  File "/home/airflow/.local/lib/python3.12/site-packages/airflow/operators/python.py", line 238, in execute
    return_value = self.execute_callable()
                   ^^^^^^^^^^^^^^^^^^^^^^^
  File "/home/airflow/.local/lib/python3.12/site-packages/airflow/operators/python.py", line 256, in execute_callable
    return runner.run(*self.op_args, **self.op_kwargs)
           ^^^^^^^^^^^^^^^^^^^^^^^^^^^^^^^^^^^^^^^^^^^
  File "/home/airflow/.local/lib/python3.12/site-packages/airflow/utils/operator_helpers.py", line 252, in run
    return self.func(*args, **kwargs)
           ^^^^^^^^^^^^^^^^^^^^^^^^^^
  File "/opt/airflow/dags/pipeline/upload_to_snowflake.py", line 43, in upload_to_snowflake
    cursor.execute(put_sql)
  File "/home/airflow/.local/lib/python3.12/site-packages/snowflake/connector/cursor.py", line 1097, in execute
    Error.errorhandler_wrapper(self.connection, self, error_class, errvalue)
  File "/home/airflow/.local/lib/python3.12/site-packages/snowflake/connector/errors.py", line 284, in errorhandler_wrapper
    handed_over = Error.hand_to_other_handler(
                  ^^^^^^^^^^^^^^^^^^^^^^^^^^^^
  File "/home/airflow/.local/lib/python3.12/site-packages/snowflake/connector/errors.py", line 339, in hand_to_other_handler
    cursor.errorhandler(connection, cursor, error_class, error_value)
  File "/home/airflow/.local/lib/python3.12/site-packages/snowflake/connector/errors.py", line 215, in default_errorhandler
    raise error_class(
snowflake.connector.errors.ProgrammingError: 002003 (02000): 01bba22f-020d-009b-000b-5e4b002d701a: SQL compilation error:
Stage 'FINAL_PROJECT.SCRAPING.DATA' does not exist or not authorized.
[2025-04-12T06:07:42.698+0000] {taskinstance.py:1225} INFO - Marking task as FAILED. dag_id=triphobo_etl_pipeline, task_id=load_attractions_snowflake, run_id=manual__2025-04-12T05:57:19.595174+00:00, execution_date=20250412T055719, start_date=20250412T060741, end_date=20250412T060742
[2025-04-12T06:07:42.708+0000] {taskinstance.py:340} INFO - ::group::Post task execution logs
[2025-04-12T06:07:42.709+0000] {standard_task_runner.py:124} ERROR - Failed to execute job 140 for task load_attractions_snowflake (002003 (02000): 01bba22f-020d-009b-000b-5e4b002d701a: SQL compilation error:
Stage 'FINAL_PROJECT.SCRAPING.DATA' does not exist or not authorized.; 1231)
Traceback (most recent call last):
  File "/home/airflow/.local/lib/python3.12/site-packages/airflow/task/task_runner/standard_task_runner.py", line 117, in _start_by_fork
    ret = args.func(args, dag=self.dag)
          ^^^^^^^^^^^^^^^^^^^^^^^^^^^^^
  File "/home/airflow/.local/lib/python3.12/site-packages/airflow/cli/cli_config.py", line 49, in command
    return func(*args, **kwargs)
           ^^^^^^^^^^^^^^^^^^^^^
  File "/home/airflow/.local/lib/python3.12/site-packages/airflow/utils/cli.py", line 116, in wrapper
    return f(*args, **kwargs)
           ^^^^^^^^^^^^^^^^^^
  File "/home/airflow/.local/lib/python3.12/site-packages/airflow/cli/commands/task_command.py", line 483, in task_run
    task_return_code = _run_task_by_selected_method(args, _dag, ti)
                       ^^^^^^^^^^^^^^^^^^^^^^^^^^^^^^^^^^^^^^^^^^^^
  File "/home/airflow/.local/lib/python3.12/site-packages/airflow/cli/commands/task_command.py", line 256, in _run_task_by_selected_method
    return _run_raw_task(args, ti)
           ^^^^^^^^^^^^^^^^^^^^^^^
  File "/home/airflow/.local/lib/python3.12/site-packages/airflow/cli/commands/task_command.py", line 341, in _run_raw_task
    return ti._run_raw_task(
           ^^^^^^^^^^^^^^^^^
  File "/home/airflow/.local/lib/python3.12/site-packages/airflow/utils/session.py", line 97, in wrapper
    return func(*args, session=session, **kwargs)
           ^^^^^^^^^^^^^^^^^^^^^^^^^^^^^^^^^^^^^^
  File "/home/airflow/.local/lib/python3.12/site-packages/airflow/models/taskinstance.py", line 3005, in _run_raw_task
    return _run_raw_task(
           ^^^^^^^^^^^^^^
  File "/home/airflow/.local/lib/python3.12/site-packages/airflow/models/taskinstance.py", line 273, in _run_raw_task
    TaskInstance._execute_task_with_callbacks(
  File "/home/airflow/.local/lib/python3.12/site-packages/airflow/models/taskinstance.py", line 3159, in _execute_task_with_callbacks
    result = self._execute_task(context, task_orig)
             ^^^^^^^^^^^^^^^^^^^^^^^^^^^^^^^^^^^^^^
  File "/home/airflow/.local/lib/python3.12/site-packages/airflow/models/taskinstance.py", line 3183, in _execute_task
    return _execute_task(self, context, task_orig)
           ^^^^^^^^^^^^^^^^^^^^^^^^^^^^^^^^^^^^^^^
  File "/home/airflow/.local/lib/python3.12/site-packages/airflow/models/taskinstance.py", line 767, in _execute_task
    result = _execute_callable(context=context, **execute_callable_kwargs)
             ^^^^^^^^^^^^^^^^^^^^^^^^^^^^^^^^^^^^^^^^^^^^^^^^^^^^^^^^^^^^^
  File "/home/airflow/.local/lib/python3.12/site-packages/airflow/models/taskinstance.py", line 733, in _execute_callable
    return ExecutionCallableRunner(
           ^^^^^^^^^^^^^^^^^^^^^^^^
  File "/home/airflow/.local/lib/python3.12/site-packages/airflow/utils/operator_helpers.py", line 252, in run
    return self.func(*args, **kwargs)
           ^^^^^^^^^^^^^^^^^^^^^^^^^^
  File "/home/airflow/.local/lib/python3.12/site-packages/airflow/models/baseoperator.py", line 422, in wrapper
    return func(self, *args, **kwargs)
           ^^^^^^^^^^^^^^^^^^^^^^^^^^^
  File "/home/airflow/.local/lib/python3.12/site-packages/airflow/operators/python.py", line 238, in execute
    return_value = self.execute_callable()
                   ^^^^^^^^^^^^^^^^^^^^^^^
  File "/home/airflow/.local/lib/python3.12/site-packages/airflow/operators/python.py", line 256, in execute_callable
    return runner.run(*self.op_args, **self.op_kwargs)
           ^^^^^^^^^^^^^^^^^^^^^^^^^^^^^^^^^^^^^^^^^^^
  File "/home/airflow/.local/lib/python3.12/site-packages/airflow/utils/operator_helpers.py", line 252, in run
    return self.func(*args, **kwargs)
           ^^^^^^^^^^^^^^^^^^^^^^^^^^
  File "/opt/airflow/dags/pipeline/upload_to_snowflake.py", line 43, in upload_to_snowflake
    cursor.execute(put_sql)
  File "/home/airflow/.local/lib/python3.12/site-packages/snowflake/connector/cursor.py", line 1097, in execute
    Error.errorhandler_wrapper(self.connection, self, error_class, errvalue)
  File "/home/airflow/.local/lib/python3.12/site-packages/snowflake/connector/errors.py", line 284, in errorhandler_wrapper
    handed_over = Error.hand_to_other_handler(
                  ^^^^^^^^^^^^^^^^^^^^^^^^^^^^
  File "/home/airflow/.local/lib/python3.12/site-packages/snowflake/connector/errors.py", line 339, in hand_to_other_handler
    cursor.errorhandler(connection, cursor, error_class, error_value)
  File "/home/airflow/.local/lib/python3.12/site-packages/snowflake/connector/errors.py", line 215, in default_errorhandler
    raise error_class(
snowflake.connector.errors.ProgrammingError: 002003 (02000): 01bba22f-020d-009b-000b-5e4b002d701a: SQL compilation error:
Stage 'FINAL_PROJECT.SCRAPING.DATA' does not exist or not authorized.
[2025-04-12T06:07:42.722+0000] {local_task_job_runner.py:266} INFO - Task exited with return code 1
[2025-04-12T06:07:42.733+0000] {taskinstance.py:3895} INFO - 0 downstream tasks scheduled from follow-on schedule check
[2025-04-12T06:07:42.734+0000] {local_task_job_runner.py:245} INFO - ::endgroup::
